2024-05-15 19:53:55,164 INFO    StreamThr :70229 [internal.py:wandb_internal():87] W&B internal server running at pid: 70229, started at: 2024-05-15 19:53:55.164205
2024-05-15 19:53:55,165 DEBUG   HandlerThread:70229 [handler.py:handle_request():144] handle_request: status
2024-05-15 19:53:55,167 INFO    WriterThread:70229 [datastore.py:open_for_write():85] open: /Users/lisa/Documents/atari/wandb/run-20240515_195355-heg6b7e1/run-heg6b7e1.wandb
2024-05-15 19:53:55,168 DEBUG   SenderThread:70229 [sender.py:send():336] send: header
2024-05-15 19:53:55,168 DEBUG   SenderThread:70229 [sender.py:send():336] send: run
2024-05-15 19:53:55,800 ERROR   SenderThread:70229 [internal_api.py:execute():245] 404 response executing GraphQL.
2024-05-15 19:53:55,800 ERROR   SenderThread:70229 [internal_api.py:execute():246] {"errors":[{"message":"entity model_compare not found during upsertBucket","path":["upsertBucket"]}],"data":{"upsertBucket":null}}
2024-05-15 19:53:55,800 ERROR   SenderThread:70229 [sender.py:send_run():931] It appears that you do not have permission to access the requested resource. Please reach out to the project owner to grant you access. If you have the correct permissions, verify that there are no issues with your networking setup.(Error 404: Not Found)
Traceback (most recent call last):
  File "/Users/lisa/anaconda3/lib/python3.10/site-packages/wandb/sdk/lib/retry.py", line 131, in __call__
    result = self._call_fn(*args, **kwargs)
  File "/Users/lisa/anaconda3/lib/python3.10/site-packages/wandb/sdk/internal/internal_api.py", line 242, in execute
    return self.client.execute(*args, **kwargs)  # type: ignore
  File "/Users/lisa/anaconda3/lib/python3.10/site-packages/wandb/vendor/gql-0.2.0/wandb_gql/client.py", line 52, in execute
    result = self._get_result(document, *args, **kwargs)
  File "/Users/lisa/anaconda3/lib/python3.10/site-packages/wandb/vendor/gql-0.2.0/wandb_gql/client.py", line 60, in _get_result
    return self.transport.execute(document, *args, **kwargs)
  File "/Users/lisa/anaconda3/lib/python3.10/site-packages/wandb/vendor/gql-0.2.0/wandb_gql/transport/requests.py", line 39, in execute
    request.raise_for_status()
  File "/Users/lisa/anaconda3/lib/python3.10/site-packages/requests/models.py", line 1021, in raise_for_status
    raise HTTPError(http_error_msg, response=self)
requests.exceptions.HTTPError: 404 Client Error: Not Found for url: https://api.wandb.ai/graphql

During handling of the above exception, another exception occurred:

Traceback (most recent call last):
  File "/Users/lisa/anaconda3/lib/python3.10/site-packages/wandb/sdk/internal/sender.py", line 929, in send_run
    self._init_run(run, config_value_dict)
  File "/Users/lisa/anaconda3/lib/python3.10/site-packages/wandb/sdk/internal/sender.py", line 968, in _init_run
    server_run, inserted, server_messages = self._api.upsert_run(
  File "/Users/lisa/anaconda3/lib/python3.10/site-packages/wandb/apis/normalize.py", line 51, in wrapper
    raise err
  File "/Users/lisa/anaconda3/lib/python3.10/site-packages/wandb/apis/normalize.py", line 25, in wrapper
    return func(*args, **kwargs)
  File "/Users/lisa/anaconda3/lib/python3.10/site-packages/wandb/sdk/internal/internal_api.py", line 1588, in upsert_run
    response = self.gql(
  File "/Users/lisa/anaconda3/lib/python3.10/site-packages/wandb/sdk/internal/internal_api.py", line 214, in gql
    ret = self._retry_gql(
  File "/Users/lisa/anaconda3/lib/python3.10/site-packages/wandb/sdk/lib/retry.py", line 147, in __call__
    retry_timedelta_triggered = check_retry_fn(e)
  File "/Users/lisa/anaconda3/lib/python3.10/site-packages/wandb/util.py", line 1091, in check_retry_fn
    return fallback_retry_fn(e)
  File "/Users/lisa/anaconda3/lib/python3.10/site-packages/wandb/util.py", line 1033, in no_retry_auth
    raise CommError(
wandb.errors.CommError: It appears that you do not have permission to access the requested resource. Please reach out to the project owner to grant you access. If you have the correct permissions, verify that there are no issues with your networking setup.(Error 404: Not Found)
2024-05-15 19:53:55,810 DEBUG   HandlerThread:70229 [handler.py:handle_request():144] handle_request: shutdown
2024-05-15 19:53:55,810 INFO    HandlerThread:70229 [handler.py:finish():842] shutting down handler
2024-05-15 19:53:56,168 INFO    WriterThread:70229 [datastore.py:close():298] close: /Users/lisa/Documents/atari/wandb/run-20240515_195355-heg6b7e1/run-heg6b7e1.wandb
2024-05-15 19:53:56,810 INFO    SenderThread:70229 [sender.py:finish():1504] shutting down sender
